<?xml version="1.0" ?>
<robot name="partnet_b3188e51216de8cce2e4961161b75547">
	<link name="base"/>
	<link name="link_0">
		<visual name="body-1">
			<origin xyz="-0.0 -0.07382042557545104 0.9226941846998236"/>
			<geometry>
				<mesh filename="textured_objs/original-1.obj"/>
			</geometry>
		</visual>
		<collision>
			<origin xyz="-0.0 -0.07382042557545104 0.9226941846998236"/>
			<geometry>
				<mesh filename="textured_objs/original-1.obj"/>
			</geometry>
		</collision>
	</link>
	<joint name="joint_0" type="revolute">
		<origin xyz="0.0 0.0 0.0"/>
		<axis xyz="1.0 -0.0 -0.0"/>
		<child link="link_0"/>
		<parent link="link_1"/>
		<limit lower="-0.025132741228718343" upper="2.4315927138784996"/>
	</joint>
	<link name="link_1">
		<visual name="lid-2">
			<origin xyz="-0.0 -0.07382042557545104 0.9226941846998236"/>
			<geometry>
				<mesh filename="textured_objs/original-3.obj"/>
			</geometry>
		</visual>
		<collision>
			<origin xyz="-0.0 -0.07382042557545104 0.9226941846998236"/>
			<geometry>
				<mesh filename="textured_objs/original-3.obj"/>
			</geometry>
		</collision>
	</link>
	<joint name="joint_1" type="revolute">
		<origin xyz="0.0 0.07382042557545104 -0.9226941846998236"/>
		<axis xyz="-1.0 0.0 0.0"/>
		<child link="link_1"/>
		<parent link="link_2"/>
		<limit lower="-0.05026548245743661" upper="2.0106192982974678"/>
	</joint>
	<link name="link_2">
		<visual name="base_body-3">
			<origin xyz="0 0 0"/>
			<geometry>
				<mesh filename="textured_objs/original-2.obj"/>
			</geometry>
		</visual>
		<collision>
			<origin xyz="0 0 0"/>
			<geometry>
				<mesh filename="textured_objs/original-2.obj"/>
			</geometry>
		</collision>
	</link>
	<joint name="joint_2" type="fixed">
		<origin rpy="1.570796326794897 0 -1.570796326794897" xyz="0 0 0"/>
		<child link="link_2"/>
		<parent link="base"/>
	</joint>
</robot>
