<?xml version="1.0" ?>
<robot name="partnet_daab8d5b-b371-404b-b11b-94564de1e0de">
	<link name="base"/>
	<link name="link_0">
		<visual name="pressing_lid-1">
			<origin xyz="-0.004700500000000003 0 -0.00026694471682328635"/>
			<geometry>
				<mesh filename="textured_objs/original-3.obj"/>
			</geometry>
		</visual>
		<collision>
			<origin xyz="-0.004700500000000003 0 -0.00026694471682328635"/>
			<geometry>
				<mesh filename="textured_objs/original-3.obj"/>
			</geometry>
		</collision>
	</link>
	<joint name="joint_0" type="continuous">
		<origin xyz="0.0 0 0.0"/>
		<axis xyz="0 1 0"/>
		<child link="link_0"/>
		<parent link="link_0_helper"/>
	</joint>
	<link name="link_1">
		<visual name="head-3">
			<origin xyz="-0.0046615 0 0.002041000000000015"/>
			<geometry>
				<mesh filename="textured_objs/original-2.obj"/>
			</geometry>
		</visual>
		<collision>
			<origin xyz="-0.0046615 0 0.002041000000000015"/>
			<geometry>
				<mesh filename="textured_objs/original-2.obj"/>
			</geometry>
		</collision>
	</link>
	<joint name="joint_1" type="continuous">
		<origin xyz="0.0 0 0.0"/>
		<axis xyz="0 -1 0"/>
		<child link="link_1"/>
		<parent link="link_1_helper"/>
	</joint>
	<link name="link_2">
		<visual name="base_body-4">
			<origin xyz="0 0 0"/>
			<geometry>
				<mesh filename="textured_objs/original-1.obj"/>
			</geometry>
		</visual>
		<collision>
			<origin xyz="0 0 0"/>
			<geometry>
				<mesh filename="textured_objs/original-1.obj"/>
			</geometry>
		</collision>
	</link>
	<joint name="joint_2" type="fixed">
		<origin rpy="1.570796326794897 0 -1.570796326794897" xyz="0 0 0"/>
		<child link="link_2"/>
		<parent link="base"/>
	</joint>
	<link name="link_0_helper"/>
	<joint name="joint_3" type="prismatic">
		<origin xyz="3.900000000000344e-05 0 0.0023079447168233014"/>
		<axis xyz="0 -1 0"/>
		<child link="link_0_helper"/>
		<parent link="link_1"/>
		<limit lower="0" upper="0.08"/>
	</joint>
	<link name="link_1_helper"/>
	<joint name="joint_4" type="prismatic">
		<origin xyz="0.0046615 0 -0.002041000000000015"/>
		<axis xyz="0 1 0"/>
		<child link="link_1_helper"/>
		<parent link="link_2"/>
		<limit lower="0" upper="0.1"/>
	</joint>
</robot>
