<?xml version="1.0" ?>
<robot name="partnet_019dff2f-8207-4ddf-8255-871060cd4bf6">
	<link name="base"/>
	<link name="link_0">
		<visual name="door-1">
			<origin xyz="0.4585415 0 -0.5808095"/>
			<geometry>
				<mesh filename="textured_objs/original-7.obj"/>
			</geometry>
		</visual>
		<visual name="door-1">
			<origin xyz="0.4585415 0 -0.5808095"/>
			<geometry>
				<mesh filename="textured_objs/original-6.obj"/>
			</geometry>
		</visual>
		<visual name="door-1">
			<origin xyz="0.4585415 0 -0.5808095"/>
			<geometry>
				<mesh filename="textured_objs/original-8.obj"/>
			</geometry>
		</visual>
		<collision>
			<origin xyz="0.4585415 0 -0.5808095"/>
			<geometry>
				<mesh filename="textured_objs/original-7.obj"/>
			</geometry>
		</collision>
		<collision>
			<origin xyz="0.4585415 0 -0.5808095"/>
			<geometry>
				<mesh filename="textured_objs/original-6.obj"/>
			</geometry>
		</collision>
		<collision>
			<origin xyz="0.4585415 0 -0.5808095"/>
			<geometry>
				<mesh filename="textured_objs/original-8.obj"/>
			</geometry>
		</collision>
	</link>
	<joint name="joint_0" type="revolute">
		<origin xyz="-0.4585415 0 0.5808095"/>
		<axis xyz="0 -1 0"/>
		<child link="link_0"/>
		<parent link="link_2"/>
		<limit lower="0.0" upper="3.141592653589793"/>
	</joint>
	<link name="link_1">
		<visual name="switch-5">
			<origin xyz="-0.3103190281377981 -0.048701999999999995 0"/>
			<geometry>
				<mesh filename="textured_objs/original-9.obj"/>
			</geometry>
		</visual>
		<collision>
			<origin xyz="-0.3103190281377981 -0.048701999999999995 0"/>
			<geometry>
				<mesh filename="textured_objs/original-9.obj"/>
			</geometry>
		</collision>
	</link>
	<joint name="joint_1" type="continuous">
		<origin xyz="0.768860528137798 0.048701999999999995 -0.5808095"/>
		<axis xyz="0 0 1"/>
		<child link="link_1"/>
		<parent link="link_0"/>
	</joint>
	<link name="link_2">
		<visual name="base_body-6">
			<origin xyz="0 0 0"/>
			<geometry>
				<mesh filename="textured_objs/original-4.obj"/>
			</geometry>
		</visual>
		<visual name="base_body-6">
			<origin xyz="0 0 0"/>
			<geometry>
				<mesh filename="textured_objs/original-3.obj"/>
			</geometry>
		</visual>
		<visual name="base_body-6">
			<origin xyz="0 0 0"/>
			<geometry>
				<mesh filename="textured_objs/original-1.obj"/>
			</geometry>
		</visual>
		<collision>
			<origin xyz="0 0 0"/>
			<geometry>
				<mesh filename="textured_objs/original-4.obj"/>
			</geometry>
		</collision>
		<collision>
			<origin xyz="0 0 0"/>
			<geometry>
				<mesh filename="textured_objs/original-3.obj"/>
			</geometry>
		</collision>
		<collision>
			<origin xyz="0 0 0"/>
			<geometry>
				<mesh filename="textured_objs/original-1.obj"/>
			</geometry>
		</collision>
	</link>
	<joint name="joint_2" type="fixed">
		<origin rpy="1.570796326794897 0 -1.570796326794897" xyz="0 0 0"/>
		<child link="link_2"/>
		<parent link="base"/>
	</joint>
</robot>
