<?xml version="1.0" ?>
<robot name="partnet_2cc108080535bc51e7a14f6d159dcd47">
	<link name="base"/>
	<link name="link_0">
		<visual name="lid-8">
			<origin xyz="0.000805884093152467 0.004672248248342605 -0.07488137958866185"/>
			<geometry>
				<mesh filename="textured_objs/original-17.obj"/>
			</geometry>
		</visual>
		<collision>
			<origin xyz="0.000805884093152467 0.004672248248342605 -0.07488137958866185"/>
			<geometry>
				<mesh filename="textured_objs/original-17.obj"/>
			</geometry>
		</collision>
	</link>
	<joint name="joint_0" type="prismatic">
		<origin xyz="-0.000805884093152467 -0.004672248248342605 0.07488137958866185"/>
		<axis xyz="-9.998538438076892e-06 0.9980590834615828 0.06227411837878444"/>
		<child link="link_0"/>
		<parent link="link_1"/>
		<limit lower="0.008000000000000007" upper="0.22799999999999998"/>
	</joint>
	<link name="link_1">
		<visual name="body-6">
			<origin xyz="0 0 0"/>
			<geometry>
				<mesh filename="textured_objs/new-1.obj"/>
			</geometry>
		</visual>
		<visual name="neck-7">
			<origin xyz="0 0 0"/>
			<geometry>
				<mesh filename="textured_objs/new-0.obj"/>
			</geometry>
		</visual>
		<collision>
			<origin xyz="0 0 0"/>
			<geometry>
				<mesh filename="textured_objs/new-1.obj"/>
			</geometry>
		</collision>
		<collision>
			<origin xyz="0 0 0"/>
			<geometry>
				<mesh filename="textured_objs/new-0.obj"/>
			</geometry>
		</collision>
	</link>
	<joint name="joint_1" type="fixed">
		<origin rpy="1.570796326794897 0 -1.570796326794897" xyz="0 0 0"/>
		<child link="link_1"/>
		<parent link="base"/>
	</joint>
</robot>
