<?xml version="1.0" ?>
<robot name="partnet_9cec36de93bb49d3f07ead639233915e">
	<link name="base"/>
	<link name="link_0">
		<visual name="body-5">
			<origin xyz="0 0 0"/>
			<geometry>
				<mesh filename="textured_objs/new-1.obj"/>
			</geometry>
		</visual>
		<collision>
			<origin xyz="0 0 0"/>
			<geometry>
				<mesh filename="textured_objs/new-1.obj"/>
			</geometry>
		</collision>
	</link>
	<joint name="joint_0" type="fixed">
		<origin rpy="1.570796326794897 0 -1.570796326794897" xyz="0 0 0"/>
		<child link="link_0"/>
		<parent link="base"/>
	</joint>
	<link name="link_1">
		<visual name="neck-6">
			<origin xyz="-0.004014355277128902 0 0.004629500000000002"/>
			<geometry>
				<mesh filename="textured_objs/original-34.obj"/>
			</geometry>
		</visual>
		<visual name="lid-7">
			<origin xyz="-0.004014355277128902 0 0.004629500000000002"/>
			<geometry>
				<mesh filename="textured_objs/original-36.obj"/>
			</geometry>
		</visual>
		<visual name="mouth-8">
			<origin xyz="-0.004014355277128902 0 0.004629500000000002"/>
			<geometry>
				<mesh filename="textured_objs/original-35.obj"/>
			</geometry>
		</visual>
		<collision>
			<origin xyz="-0.004014355277128902 0 0.004629500000000002"/>
			<geometry>
				<mesh filename="textured_objs/original-34.obj"/>
			</geometry>
		</collision>
		<collision>
			<origin xyz="-0.004014355277128902 0 0.004629500000000002"/>
			<geometry>
				<mesh filename="textured_objs/original-36.obj"/>
			</geometry>
		</collision>
		<collision>
			<origin xyz="-0.004014355277128902 0 0.004629500000000002"/>
			<geometry>
				<mesh filename="textured_objs/original-35.obj"/>
			</geometry>
		</collision>
	</link>
	<joint name="joint_1" type="continuous">
		<origin xyz="0.0 0 0.0"/>
		<axis xyz="0 1 0"/>
		<child link="link_1"/>
		<parent link="link_1_helper"/>
	</joint>
	<link name="link_1_helper"/>
	<joint name="joint_2" type="prismatic">
		<origin xyz="0.004014355277128902 0 -0.004629500000000002"/>
		<axis xyz="0 1 0"/>
		<child link="link_1_helper"/>
		<parent link="link_0"/>
		<limit lower="-0.008000000000000007" upper="0.03200000000000003"/>
	</joint>
</robot>
