<?xml version="1.0" ?>
<robot name="partnet_7852a457e59fd546d26c2593d1870bdb">
	<link name="base"/>
	<link name="link_0">
		<visual name="button-1">
			<origin xyz="0 0 0"/>
			<geometry>
				<mesh filename="textured_objs/original-202.obj"/>
			</geometry>
		</visual>
		<visual name="button-1">
			<origin xyz="0 0 0"/>
			<geometry>
				<mesh filename="textured_objs/original-203.obj"/>
			</geometry>
		</visual>
		<collision>
			<origin xyz="0 0 0"/>
			<geometry>
				<mesh filename="textured_objs/original-202.obj"/>
			</geometry>
		</collision>
		<collision>
			<origin xyz="0 0 0"/>
			<geometry>
				<mesh filename="textured_objs/original-203.obj"/>
			</geometry>
		</collision>
	</link>
	<joint name="joint_0" type="prismatic">
		<origin xyz="0 0 0"/>
		<axis xyz="0 0 -1"/>
		<child link="link_0"/>
		<parent link="link_42"/>
		<limit lower="0" upper="0.01"/>
	</joint>
	<link name="link_1">
		<visual name="button-2">
			<origin xyz="0 0 0"/>
			<geometry>
				<mesh filename="textured_objs/original-204.obj"/>
			</geometry>
		</visual>
		<visual name="button-2">
			<origin xyz="0 0 0"/>
			<geometry>
				<mesh filename="textured_objs/original-205.obj"/>
			</geometry>
		</visual>
		<collision>
			<origin xyz="0 0 0"/>
			<geometry>
				<mesh filename="textured_objs/original-204.obj"/>
			</geometry>
		</collision>
		<collision>
			<origin xyz="0 0 0"/>
			<geometry>
				<mesh filename="textured_objs/original-205.obj"/>
			</geometry>
		</collision>
	</link>
	<joint name="joint_1" type="prismatic">
		<origin xyz="0 0 0"/>
		<axis xyz="0 0 -1"/>
		<child link="link_1"/>
		<parent link="link_42"/>
		<limit lower="0" upper="0.01"/>
	</joint>
	<link name="link_2">
		<visual name="button-3">
			<origin xyz="0 0 0"/>
			<geometry>
				<mesh filename="textured_objs/original-207.obj"/>
			</geometry>
		</visual>
		<visual name="button-3">
			<origin xyz="0 0 0"/>
			<geometry>
				<mesh filename="textured_objs/original-206.obj"/>
			</geometry>
		</visual>
		<visual name="button-3">
			<origin xyz="0 0 0"/>
			<geometry>
				<mesh filename="textured_objs/original-208.obj"/>
			</geometry>
		</visual>
		<collision>
			<origin xyz="0 0 0"/>
			<geometry>
				<mesh filename="textured_objs/original-207.obj"/>
			</geometry>
		</collision>
		<collision>
			<origin xyz="0 0 0"/>
			<geometry>
				<mesh filename="textured_objs/original-206.obj"/>
			</geometry>
		</collision>
		<collision>
			<origin xyz="0 0 0"/>
			<geometry>
				<mesh filename="textured_objs/original-208.obj"/>
			</geometry>
		</collision>
	</link>
	<joint name="joint_2" type="prismatic">
		<origin xyz="0 0 0"/>
		<axis xyz="0 0 -1"/>
		<child link="link_2"/>
		<parent link="link_42"/>
		<limit lower="0" upper="0.01"/>
	</joint>
	<link name="link_3">
		<visual name="button-4">
			<origin xyz="0 0 0"/>
			<geometry>
				<mesh filename="textured_objs/original-210.obj"/>
			</geometry>
		</visual>
		<visual name="button-4">
			<origin xyz="0 0 0"/>
			<geometry>
				<mesh filename="textured_objs/original-209.obj"/>
			</geometry>
		</visual>
		<collision>
			<origin xyz="0 0 0"/>
			<geometry>
				<mesh filename="textured_objs/original-210.obj"/>
			</geometry>
		</collision>
		<collision>
			<origin xyz="0 0 0"/>
			<geometry>
				<mesh filename="textured_objs/original-209.obj"/>
			</geometry>
		</collision>
	</link>
	<joint name="joint_3" type="prismatic">
		<origin xyz="0 0 0"/>
		<axis xyz="0 0 -1"/>
		<child link="link_3"/>
		<parent link="link_42"/>
		<limit lower="0" upper="0.01"/>
	</joint>
	<link name="link_4">
		<visual name="button-5">
			<origin xyz="0 0 0"/>
			<geometry>
				<mesh filename="textured_objs/original-212.obj"/>
			</geometry>
		</visual>
		<visual name="button-5">
			<origin xyz="0 0 0"/>
			<geometry>
				<mesh filename="textured_objs/original-211.obj"/>
			</geometry>
		</visual>
		<collision>
			<origin xyz="0 0 0"/>
			<geometry>
				<mesh filename="textured_objs/original-212.obj"/>
			</geometry>
		</collision>
		<collision>
			<origin xyz="0 0 0"/>
			<geometry>
				<mesh filename="textured_objs/original-211.obj"/>
			</geometry>
		</collision>
	</link>
	<joint name="joint_4" type="prismatic">
		<origin xyz="0 0 0"/>
		<axis xyz="0 0 -1"/>
		<child link="link_4"/>
		<parent link="link_42"/>
		<limit lower="0" upper="0.01"/>
	</joint>
	<link name="link_5">
		<visual name="button-6">
			<origin xyz="0 0 0"/>
			<geometry>
				<mesh filename="textured_objs/original-151.obj"/>
			</geometry>
		</visual>
		<visual name="button-6">
			<origin xyz="0 0 0"/>
			<geometry>
				<mesh filename="textured_objs/original-150.obj"/>
			</geometry>
		</visual>
		<visual name="button-6">
			<origin xyz="0 0 0"/>
			<geometry>
				<mesh filename="textured_objs/original-152.obj"/>
			</geometry>
		</visual>
		<collision>
			<origin xyz="0 0 0"/>
			<geometry>
				<mesh filename="textured_objs/original-151.obj"/>
			</geometry>
		</collision>
		<collision>
			<origin xyz="0 0 0"/>
			<geometry>
				<mesh filename="textured_objs/original-150.obj"/>
			</geometry>
		</collision>
		<collision>
			<origin xyz="0 0 0"/>
			<geometry>
				<mesh filename="textured_objs/original-152.obj"/>
			</geometry>
		</collision>
	</link>
	<joint name="joint_5" type="prismatic">
		<origin xyz="0 0 0"/>
		<axis xyz="0 0 -1"/>
		<child link="link_5"/>
		<parent link="link_42"/>
		<limit lower="0" upper="0.01"/>
	</joint>
	<link name="link_6">
		<visual name="button-7">
			<origin xyz="0 0 0"/>
			<geometry>
				<mesh filename="textured_objs/original-155.obj"/>
			</geometry>
		</visual>
		<visual name="button-7">
			<origin xyz="0 0 0"/>
			<geometry>
				<mesh filename="textured_objs/original-157.obj"/>
			</geometry>
		</visual>
		<visual name="button-7">
			<origin xyz="0 0 0"/>
			<geometry>
				<mesh filename="textured_objs/original-161.obj"/>
			</geometry>
		</visual>
		<visual name="button-7">
			<origin xyz="0 0 0"/>
			<geometry>
				<mesh filename="textured_objs/original-156.obj"/>
			</geometry>
		</visual>
		<visual name="button-7">
			<origin xyz="0 0 0"/>
			<geometry>
				<mesh filename="textured_objs/original-158.obj"/>
			</geometry>
		</visual>
		<visual name="button-7">
			<origin xyz="0 0 0"/>
			<geometry>
				<mesh filename="textured_objs/original-159.obj"/>
			</geometry>
		</visual>
		<visual name="button-7">
			<origin xyz="0 0 0"/>
			<geometry>
				<mesh filename="textured_objs/original-160.obj"/>
			</geometry>
		</visual>
		<collision>
			<origin xyz="0 0 0"/>
			<geometry>
				<mesh filename="textured_objs/original-155.obj"/>
			</geometry>
		</collision>
		<collision>
			<origin xyz="0 0 0"/>
			<geometry>
				<mesh filename="textured_objs/original-157.obj"/>
			</geometry>
		</collision>
		<collision>
			<origin xyz="0 0 0"/>
			<geometry>
				<mesh filename="textured_objs/original-161.obj"/>
			</geometry>
		</collision>
		<collision>
			<origin xyz="0 0 0"/>
			<geometry>
				<mesh filename="textured_objs/original-156.obj"/>
			</geometry>
		</collision>
		<collision>
			<origin xyz="0 0 0"/>
			<geometry>
				<mesh filename="textured_objs/original-158.obj"/>
			</geometry>
		</collision>
		<collision>
			<origin xyz="0 0 0"/>
			<geometry>
				<mesh filename="textured_objs/original-159.obj"/>
			</geometry>
		</collision>
		<collision>
			<origin xyz="0 0 0"/>
			<geometry>
				<mesh filename="textured_objs/original-160.obj"/>
			</geometry>
		</collision>
	</link>
	<joint name="joint_6" type="prismatic">
		<origin xyz="0 0 0"/>
		<axis xyz="0 0 -1"/>
		<child link="link_6"/>
		<parent link="link_42"/>
		<limit lower="0" upper="0.01"/>
	</joint>
	<link name="link_7">
		<visual name="button-8">
			<origin xyz="0 0 0"/>
			<geometry>
				<mesh filename="textured_objs/original-140.obj"/>
			</geometry>
		</visual>
		<visual name="button-8">
			<origin xyz="0 0 0"/>
			<geometry>
				<mesh filename="textured_objs/original-137.obj"/>
			</geometry>
		</visual>
		<visual name="button-8">
			<origin xyz="0 0 0"/>
			<geometry>
				<mesh filename="textured_objs/original-138.obj"/>
			</geometry>
		</visual>
		<visual name="button-8">
			<origin xyz="0 0 0"/>
			<geometry>
				<mesh filename="textured_objs/original-135.obj"/>
			</geometry>
		</visual>
		<visual name="button-8">
			<origin xyz="0 0 0"/>
			<geometry>
				<mesh filename="textured_objs/original-139.obj"/>
			</geometry>
		</visual>
		<visual name="button-8">
			<origin xyz="0 0 0"/>
			<geometry>
				<mesh filename="textured_objs/original-141.obj"/>
			</geometry>
		</visual>
		<visual name="button-8">
			<origin xyz="0 0 0"/>
			<geometry>
				<mesh filename="textured_objs/original-143.obj"/>
			</geometry>
		</visual>
		<visual name="button-8">
			<origin xyz="0 0 0"/>
			<geometry>
				<mesh filename="textured_objs/original-142.obj"/>
			</geometry>
		</visual>
		<visual name="button-8">
			<origin xyz="0 0 0"/>
			<geometry>
				<mesh filename="textured_objs/original-136.obj"/>
			</geometry>
		</visual>
		<collision>
			<origin xyz="0 0 0"/>
			<geometry>
				<mesh filename="textured_objs/original-140.obj"/>
			</geometry>
		</collision>
		<collision>
			<origin xyz="0 0 0"/>
			<geometry>
				<mesh filename="textured_objs/original-137.obj"/>
			</geometry>
		</collision>
		<collision>
			<origin xyz="0 0 0"/>
			<geometry>
				<mesh filename="textured_objs/original-138.obj"/>
			</geometry>
		</collision>
		<collision>
			<origin xyz="0 0 0"/>
			<geometry>
				<mesh filename="textured_objs/original-135.obj"/>
			</geometry>
		</collision>
		<collision>
			<origin xyz="0 0 0"/>
			<geometry>
				<mesh filename="textured_objs/original-139.obj"/>
			</geometry>
		</collision>
		<collision>
			<origin xyz="0 0 0"/>
			<geometry>
				<mesh filename="textured_objs/original-141.obj"/>
			</geometry>
		</collision>
		<collision>
			<origin xyz="0 0 0"/>
			<geometry>
				<mesh filename="textured_objs/original-143.obj"/>
			</geometry>
		</collision>
		<collision>
			<origin xyz="0 0 0"/>
			<geometry>
				<mesh filename="textured_objs/original-142.obj"/>
			</geometry>
		</collision>
		<collision>
			<origin xyz="0 0 0"/>
			<geometry>
				<mesh filename="textured_objs/original-136.obj"/>
			</geometry>
		</collision>
	</link>
	<joint name="joint_7" type="prismatic">
		<origin xyz="0 0 0"/>
		<axis xyz="0 0 -1"/>
		<child link="link_7"/>
		<parent link="link_42"/>
		<limit lower="0" upper="0.01"/>
	</joint>
	<link name="link_8">
		<visual name="button-9">
			<origin xyz="0 0 0"/>
			<geometry>
				<mesh filename="textured_objs/original-163.obj"/>
			</geometry>
		</visual>
		<visual name="button-9">
			<origin xyz="0 0 0"/>
			<geometry>
				<mesh filename="textured_objs/original-164.obj"/>
			</geometry>
		</visual>
		<collision>
			<origin xyz="0 0 0"/>
			<geometry>
				<mesh filename="textured_objs/original-163.obj"/>
			</geometry>
		</collision>
		<collision>
			<origin xyz="0 0 0"/>
			<geometry>
				<mesh filename="textured_objs/original-164.obj"/>
			</geometry>
		</collision>
	</link>
	<joint name="joint_8" type="prismatic">
		<origin xyz="0 0 0"/>
		<axis xyz="0 0 -1"/>
		<child link="link_8"/>
		<parent link="link_42"/>
		<limit lower="0" upper="0.01"/>
	</joint>
	<link name="link_9">
		<visual name="button-10">
			<origin xyz="0 0 0"/>
			<geometry>
				<mesh filename="textured_objs/original-167.obj"/>
			</geometry>
		</visual>
		<visual name="button-10">
			<origin xyz="0 0 0"/>
			<geometry>
				<mesh filename="textured_objs/original-166.obj"/>
			</geometry>
		</visual>
		<collision>
			<origin xyz="0 0 0"/>
			<geometry>
				<mesh filename="textured_objs/original-167.obj"/>
			</geometry>
		</collision>
		<collision>
			<origin xyz="0 0 0"/>
			<geometry>
				<mesh filename="textured_objs/original-166.obj"/>
			</geometry>
		</collision>
	</link>
	<joint name="joint_9" type="prismatic">
		<origin xyz="0 0 0"/>
		<axis xyz="0 0 -1"/>
		<child link="link_9"/>
		<parent link="link_42"/>
		<limit lower="0" upper="0.01"/>
	</joint>
	<link name="link_10">
		<visual name="button-11">
			<origin xyz="0 0 0"/>
			<geometry>
				<mesh filename="textured_objs/original-169.obj"/>
			</geometry>
		</visual>
		<visual name="button-11">
			<origin xyz="0 0 0"/>
			<geometry>
				<mesh filename="textured_objs/original-170.obj"/>
			</geometry>
		</visual>
		<collision>
			<origin xyz="0 0 0"/>
			<geometry>
				<mesh filename="textured_objs/original-169.obj"/>
			</geometry>
		</collision>
		<collision>
			<origin xyz="0 0 0"/>
			<geometry>
				<mesh filename="textured_objs/original-170.obj"/>
			</geometry>
		</collision>
	</link>
	<joint name="joint_10" type="prismatic">
		<origin xyz="0 0 0"/>
		<axis xyz="0 0 -1"/>
		<child link="link_10"/>
		<parent link="link_42"/>
		<limit lower="0" upper="0.01"/>
	</joint>
	<link name="link_11">
		<visual name="button-12">
			<origin xyz="0 0 0"/>
			<geometry>
				<mesh filename="textured_objs/original-173.obj"/>
			</geometry>
		</visual>
		<visual name="button-12">
			<origin xyz="0 0 0"/>
			<geometry>
				<mesh filename="textured_objs/original-172.obj"/>
			</geometry>
		</visual>
		<collision>
			<origin xyz="0 0 0"/>
			<geometry>
				<mesh filename="textured_objs/original-173.obj"/>
			</geometry>
		</collision>
		<collision>
			<origin xyz="0 0 0"/>
			<geometry>
				<mesh filename="textured_objs/original-172.obj"/>
			</geometry>
		</collision>
	</link>
	<joint name="joint_11" type="prismatic">
		<origin xyz="0 0 0"/>
		<axis xyz="0 0 -1"/>
		<child link="link_11"/>
		<parent link="link_42"/>
		<limit lower="0" upper="0.01"/>
	</joint>
	<link name="link_12">
		<visual name="button-13">
			<origin xyz="0 0 0"/>
			<geometry>
				<mesh filename="textured_objs/original-117.obj"/>
			</geometry>
		</visual>
		<visual name="button-13">
			<origin xyz="0 0 0"/>
			<geometry>
				<mesh filename="textured_objs/original-116.obj"/>
			</geometry>
		</visual>
		<visual name="button-13">
			<origin xyz="0 0 0"/>
			<geometry>
				<mesh filename="textured_objs/original-118.obj"/>
			</geometry>
		</visual>
		<visual name="button-13">
			<origin xyz="0 0 0"/>
			<geometry>
				<mesh filename="textured_objs/original-119.obj"/>
			</geometry>
		</visual>
		<visual name="button-13">
			<origin xyz="0 0 0"/>
			<geometry>
				<mesh filename="textured_objs/original-195.obj"/>
			</geometry>
		</visual>
		<collision>
			<origin xyz="0 0 0"/>
			<geometry>
				<mesh filename="textured_objs/original-117.obj"/>
			</geometry>
		</collision>
		<collision>
			<origin xyz="0 0 0"/>
			<geometry>
				<mesh filename="textured_objs/original-116.obj"/>
			</geometry>
		</collision>
		<collision>
			<origin xyz="0 0 0"/>
			<geometry>
				<mesh filename="textured_objs/original-118.obj"/>
			</geometry>
		</collision>
		<collision>
			<origin xyz="0 0 0"/>
			<geometry>
				<mesh filename="textured_objs/original-119.obj"/>
			</geometry>
		</collision>
		<collision>
			<origin xyz="0 0 0"/>
			<geometry>
				<mesh filename="textured_objs/original-195.obj"/>
			</geometry>
		</collision>
	</link>
	<joint name="joint_12" type="prismatic">
		<origin xyz="0 0 0"/>
		<axis xyz="0 0 -1"/>
		<child link="link_12"/>
		<parent link="link_42"/>
		<limit lower="0" upper="0.01"/>
	</joint>
	<link name="link_13">
		<visual name="button-14">
			<origin xyz="-0.2275651375875013 0.37 -0.09"/>
			<geometry>
				<mesh filename="textured_objs/original-184.obj"/>
			</geometry>
		</visual>
		<visual name="button-14">
			<origin xyz="-0.2275651375875013 0.37 -0.09"/>
			<geometry>
				<mesh filename="textured_objs/original-185.obj"/>
			</geometry>
		</visual>
		<collision>
			<origin xyz="-0.2275651375875013 0.37 -0.09"/>
			<geometry>
				<mesh filename="textured_objs/original-184.obj"/>
			</geometry>
		</collision>
		<collision>
			<origin xyz="-0.2275651375875013 0.37 -0.09"/>
			<geometry>
				<mesh filename="textured_objs/original-185.obj"/>
			</geometry>
		</collision>
	</link>
	<joint name="joint_13" type="revolute">
		<origin xyz="0.2275651375875013 -0.37 0.09"/>
		<axis xyz="1 0 0"/>
		<child link="link_13"/>
		<parent link="link_42"/>
		<limit lower="0.0" upper="0.17453292519943295"/>
	</joint>
	<link name="link_14">
		<visual name="button-15">
			<origin xyz="0 0 0"/>
			<geometry>
				<mesh filename="textured_objs/original-126.obj"/>
			</geometry>
		</visual>
		<visual name="button-15">
			<origin xyz="0 0 0"/>
			<geometry>
				<mesh filename="textured_objs/original-124.obj"/>
			</geometry>
		</visual>
		<visual name="button-15">
			<origin xyz="0 0 0"/>
			<geometry>
				<mesh filename="textured_objs/original-123.obj"/>
			</geometry>
		</visual>
		<visual name="button-15">
			<origin xyz="0 0 0"/>
			<geometry>
				<mesh filename="textured_objs/original-125.obj"/>
			</geometry>
		</visual>
		<visual name="button-15">
			<origin xyz="0 0 0"/>
			<geometry>
				<mesh filename="textured_objs/original-127.obj"/>
			</geometry>
		</visual>
		<visual name="button-15">
			<origin xyz="0 0 0"/>
			<geometry>
				<mesh filename="textured_objs/original-128.obj"/>
			</geometry>
		</visual>
		<visual name="button-15">
			<origin xyz="0 0 0"/>
			<geometry>
				<mesh filename="textured_objs/original-197.obj"/>
			</geometry>
		</visual>
		<collision>
			<origin xyz="0 0 0"/>
			<geometry>
				<mesh filename="textured_objs/original-126.obj"/>
			</geometry>
		</collision>
		<collision>
			<origin xyz="0 0 0"/>
			<geometry>
				<mesh filename="textured_objs/original-124.obj"/>
			</geometry>
		</collision>
		<collision>
			<origin xyz="0 0 0"/>
			<geometry>
				<mesh filename="textured_objs/original-123.obj"/>
			</geometry>
		</collision>
		<collision>
			<origin xyz="0 0 0"/>
			<geometry>
				<mesh filename="textured_objs/original-125.obj"/>
			</geometry>
		</collision>
		<collision>
			<origin xyz="0 0 0"/>
			<geometry>
				<mesh filename="textured_objs/original-127.obj"/>
			</geometry>
		</collision>
		<collision>
			<origin xyz="0 0 0"/>
			<geometry>
				<mesh filename="textured_objs/original-128.obj"/>
			</geometry>
		</collision>
		<collision>
			<origin xyz="0 0 0"/>
			<geometry>
				<mesh filename="textured_objs/original-197.obj"/>
			</geometry>
		</collision>
	</link>
	<joint name="joint_14" type="prismatic">
		<origin xyz="0 0 0"/>
		<axis xyz="0 0 -1"/>
		<child link="link_14"/>
		<parent link="link_42"/>
		<limit lower="0" upper="0.01"/>
	</joint>
	<link name="link_15">
		<visual name="button-16">
			<origin xyz="0 0 0"/>
			<geometry>
				<mesh filename="textured_objs/original-201.obj"/>
			</geometry>
		</visual>
		<visual name="button-16">
			<origin xyz="0 0 0"/>
			<geometry>
				<mesh filename="textured_objs/original-200.obj"/>
			</geometry>
		</visual>
		<collision>
			<origin xyz="0 0 0"/>
			<geometry>
				<mesh filename="textured_objs/original-201.obj"/>
			</geometry>
		</collision>
		<collision>
			<origin xyz="0 0 0"/>
			<geometry>
				<mesh filename="textured_objs/original-200.obj"/>
			</geometry>
		</collision>
	</link>
	<joint name="joint_15" type="prismatic">
		<origin xyz="0 0 0"/>
		<axis xyz="0 0 -1"/>
		<child link="link_15"/>
		<parent link="link_42"/>
		<limit lower="0" upper="0.01"/>
	</joint>
	<link name="link_16">
		<visual name="button-17">
			<origin xyz="0 0 0"/>
			<geometry>
				<mesh filename="textured_objs/original-188.obj"/>
			</geometry>
		</visual>
		<visual name="button-17">
			<origin xyz="0 0 0"/>
			<geometry>
				<mesh filename="textured_objs/original-186.obj"/>
			</geometry>
		</visual>
		<visual name="button-17">
			<origin xyz="0 0 0"/>
			<geometry>
				<mesh filename="textured_objs/original-187.obj"/>
			</geometry>
		</visual>
		<collision>
			<origin xyz="0 0 0"/>
			<geometry>
				<mesh filename="textured_objs/original-188.obj"/>
			</geometry>
		</collision>
		<collision>
			<origin xyz="0 0 0"/>
			<geometry>
				<mesh filename="textured_objs/original-186.obj"/>
			</geometry>
		</collision>
		<collision>
			<origin xyz="0 0 0"/>
			<geometry>
				<mesh filename="textured_objs/original-187.obj"/>
			</geometry>
		</collision>
	</link>
	<joint name="joint_16" type="prismatic">
		<origin xyz="0 0 0"/>
		<axis xyz="0 0 -1"/>
		<child link="link_16"/>
		<parent link="link_42"/>
		<limit lower="0" upper="0.01"/>
	</joint>
	<link name="link_17">
		<visual name="button-18">
			<origin xyz="0 0 0"/>
			<geometry>
				<mesh filename="textured_objs/original-190.obj"/>
			</geometry>
		</visual>
		<visual name="button-18">
			<origin xyz="0 0 0"/>
			<geometry>
				<mesh filename="textured_objs/original-189.obj"/>
			</geometry>
		</visual>
		<collision>
			<origin xyz="0 0 0"/>
			<geometry>
				<mesh filename="textured_objs/original-190.obj"/>
			</geometry>
		</collision>
		<collision>
			<origin xyz="0 0 0"/>
			<geometry>
				<mesh filename="textured_objs/original-189.obj"/>
			</geometry>
		</collision>
	</link>
	<joint name="joint_17" type="prismatic">
		<origin xyz="0 0 0"/>
		<axis xyz="0 0 -1"/>
		<child link="link_17"/>
		<parent link="link_42"/>
		<limit lower="0" upper="0.01"/>
	</joint>
	<link name="link_18">
		<visual name="button-19">
			<origin xyz="0 0 0"/>
			<geometry>
				<mesh filename="textured_objs/original-68.obj"/>
			</geometry>
		</visual>
		<visual name="button-19">
			<origin xyz="0 0 0"/>
			<geometry>
				<mesh filename="textured_objs/original-67.obj"/>
			</geometry>
		</visual>
		<visual name="button-19">
			<origin xyz="0 0 0"/>
			<geometry>
				<mesh filename="textured_objs/original-66.obj"/>
			</geometry>
		</visual>
		<visual name="button-19">
			<origin xyz="0 0 0"/>
			<geometry>
				<mesh filename="textured_objs/original-69.obj"/>
			</geometry>
		</visual>
		<visual name="button-19">
			<origin xyz="0 0 0"/>
			<geometry>
				<mesh filename="textured_objs/original-65.obj"/>
			</geometry>
		</visual>
		<collision>
			<origin xyz="0 0 0"/>
			<geometry>
				<mesh filename="textured_objs/original-68.obj"/>
			</geometry>
		</collision>
		<collision>
			<origin xyz="0 0 0"/>
			<geometry>
				<mesh filename="textured_objs/original-67.obj"/>
			</geometry>
		</collision>
		<collision>
			<origin xyz="0 0 0"/>
			<geometry>
				<mesh filename="textured_objs/original-66.obj"/>
			</geometry>
		</collision>
		<collision>
			<origin xyz="0 0 0"/>
			<geometry>
				<mesh filename="textured_objs/original-69.obj"/>
			</geometry>
		</collision>
		<collision>
			<origin xyz="0 0 0"/>
			<geometry>
				<mesh filename="textured_objs/original-65.obj"/>
			</geometry>
		</collision>
	</link>
	<joint name="joint_18" type="prismatic">
		<origin xyz="0 0 0"/>
		<axis xyz="0 0 -1"/>
		<child link="link_18"/>
		<parent link="link_42"/>
		<limit lower="0" upper="0.01"/>
	</joint>
	<link name="link_19">
		<visual name="button-20">
			<origin xyz="-0.2275651375875013 0.19 -0.09"/>
			<geometry>
				<mesh filename="textured_objs/original-198.obj"/>
			</geometry>
		</visual>
		<visual name="button-20">
			<origin xyz="-0.2275651375875013 0.19 -0.09"/>
			<geometry>
				<mesh filename="textured_objs/original-199.obj"/>
			</geometry>
		</visual>
		<collision>
			<origin xyz="-0.2275651375875013 0.19 -0.09"/>
			<geometry>
				<mesh filename="textured_objs/original-198.obj"/>
			</geometry>
		</collision>
		<collision>
			<origin xyz="-0.2275651375875013 0.19 -0.09"/>
			<geometry>
				<mesh filename="textured_objs/original-199.obj"/>
			</geometry>
		</collision>
	</link>
	<joint name="joint_19" type="revolute">
		<origin xyz="0.2275651375875013 -0.19 0.09"/>
		<axis xyz="-1 0 0"/>
		<child link="link_19"/>
		<parent link="link_42"/>
		<limit lower="-0.0" upper="0.17453292519943295"/>
	</joint>
	<link name="link_20">
		<visual name="button-21">
			<origin xyz="0 0 0"/>
			<geometry>
				<mesh filename="textured_objs/original-50.obj"/>
			</geometry>
		</visual>
		<visual name="button-21">
			<origin xyz="0 0 0"/>
			<geometry>
				<mesh filename="textured_objs/original-51.obj"/>
			</geometry>
		</visual>
		<visual name="button-21">
			<origin xyz="0 0 0"/>
			<geometry>
				<mesh filename="textured_objs/original-52.obj"/>
			</geometry>
		</visual>
		<visual name="button-21">
			<origin xyz="0 0 0"/>
			<geometry>
				<mesh filename="textured_objs/original-53.obj"/>
			</geometry>
		</visual>
		<visual name="button-21">
			<origin xyz="0 0 0"/>
			<geometry>
				<mesh filename="textured_objs/original-55.obj"/>
			</geometry>
		</visual>
		<visual name="button-21">
			<origin xyz="0 0 0"/>
			<geometry>
				<mesh filename="textured_objs/original-54.obj"/>
			</geometry>
		</visual>
		<collision>
			<origin xyz="0 0 0"/>
			<geometry>
				<mesh filename="textured_objs/original-50.obj"/>
			</geometry>
		</collision>
		<collision>
			<origin xyz="0 0 0"/>
			<geometry>
				<mesh filename="textured_objs/original-51.obj"/>
			</geometry>
		</collision>
		<collision>
			<origin xyz="0 0 0"/>
			<geometry>
				<mesh filename="textured_objs/original-52.obj"/>
			</geometry>
		</collision>
		<collision>
			<origin xyz="0 0 0"/>
			<geometry>
				<mesh filename="textured_objs/original-53.obj"/>
			</geometry>
		</collision>
		<collision>
			<origin xyz="0 0 0"/>
			<geometry>
				<mesh filename="textured_objs/original-55.obj"/>
			</geometry>
		</collision>
		<collision>
			<origin xyz="0 0 0"/>
			<geometry>
				<mesh filename="textured_objs/original-54.obj"/>
			</geometry>
		</collision>
	</link>
	<joint name="joint_20" type="prismatic">
		<origin xyz="0 0 0"/>
		<axis xyz="0 0 -1"/>
		<child link="link_20"/>
		<parent link="link_42"/>
		<limit lower="0" upper="0.01"/>
	</joint>
	<link name="link_21">
		<visual name="button-22">
			<origin xyz="0 0 0"/>
			<geometry>
				<mesh filename="textured_objs/original-43.obj"/>
			</geometry>
		</visual>
		<visual name="button-22">
			<origin xyz="0 0 0"/>
			<geometry>
				<mesh filename="textured_objs/original-40.obj"/>
			</geometry>
		</visual>
		<visual name="button-22">
			<origin xyz="0 0 0"/>
			<geometry>
				<mesh filename="textured_objs/original-41.obj"/>
			</geometry>
		</visual>
		<visual name="button-22">
			<origin xyz="0 0 0"/>
			<geometry>
				<mesh filename="textured_objs/original-42.obj"/>
			</geometry>
		</visual>
		<visual name="button-22">
			<origin xyz="0 0 0"/>
			<geometry>
				<mesh filename="textured_objs/original-44.obj"/>
			</geometry>
		</visual>
		<visual name="button-22">
			<origin xyz="0 0 0"/>
			<geometry>
				<mesh filename="textured_objs/original-45.obj"/>
			</geometry>
		</visual>
		<visual name="button-22">
			<origin xyz="0 0 0"/>
			<geometry>
				<mesh filename="textured_objs/original-47.obj"/>
			</geometry>
		</visual>
		<visual name="button-22">
			<origin xyz="0 0 0"/>
			<geometry>
				<mesh filename="textured_objs/original-46.obj"/>
			</geometry>
		</visual>
		<collision>
			<origin xyz="0 0 0"/>
			<geometry>
				<mesh filename="textured_objs/original-43.obj"/>
			</geometry>
		</collision>
		<collision>
			<origin xyz="0 0 0"/>
			<geometry>
				<mesh filename="textured_objs/original-40.obj"/>
			</geometry>
		</collision>
		<collision>
			<origin xyz="0 0 0"/>
			<geometry>
				<mesh filename="textured_objs/original-41.obj"/>
			</geometry>
		</collision>
		<collision>
			<origin xyz="0 0 0"/>
			<geometry>
				<mesh filename="textured_objs/original-42.obj"/>
			</geometry>
		</collision>
		<collision>
			<origin xyz="0 0 0"/>
			<geometry>
				<mesh filename="textured_objs/original-44.obj"/>
			</geometry>
		</collision>
		<collision>
			<origin xyz="0 0 0"/>
			<geometry>
				<mesh filename="textured_objs/original-45.obj"/>
			</geometry>
		</collision>
		<collision>
			<origin xyz="0 0 0"/>
			<geometry>
				<mesh filename="textured_objs/original-47.obj"/>
			</geometry>
		</collision>
		<collision>
			<origin xyz="0 0 0"/>
			<geometry>
				<mesh filename="textured_objs/original-46.obj"/>
			</geometry>
		</collision>
	</link>
	<joint name="joint_21" type="prismatic">
		<origin xyz="0 0 0"/>
		<axis xyz="0 0 -1"/>
		<child link="link_21"/>
		<parent link="link_42"/>
		<limit lower="0" upper="0.01"/>
	</joint>
	<link name="link_22">
		<visual name="button-23">
			<origin xyz="0 0 0"/>
			<geometry>
				<mesh filename="textured_objs/original-62.obj"/>
			</geometry>
		</visual>
		<visual name="button-23">
			<origin xyz="0 0 0"/>
			<geometry>
				<mesh filename="textured_objs/original-58.obj"/>
			</geometry>
		</visual>
		<visual name="button-23">
			<origin xyz="0 0 0"/>
			<geometry>
				<mesh filename="textured_objs/original-59.obj"/>
			</geometry>
		</visual>
		<visual name="button-23">
			<origin xyz="0 0 0"/>
			<geometry>
				<mesh filename="textured_objs/original-60.obj"/>
			</geometry>
		</visual>
		<visual name="button-23">
			<origin xyz="0 0 0"/>
			<geometry>
				<mesh filename="textured_objs/original-61.obj"/>
			</geometry>
		</visual>
		<collision>
			<origin xyz="0 0 0"/>
			<geometry>
				<mesh filename="textured_objs/original-62.obj"/>
			</geometry>
		</collision>
		<collision>
			<origin xyz="0 0 0"/>
			<geometry>
				<mesh filename="textured_objs/original-58.obj"/>
			</geometry>
		</collision>
		<collision>
			<origin xyz="0 0 0"/>
			<geometry>
				<mesh filename="textured_objs/original-59.obj"/>
			</geometry>
		</collision>
		<collision>
			<origin xyz="0 0 0"/>
			<geometry>
				<mesh filename="textured_objs/original-60.obj"/>
			</geometry>
		</collision>
		<collision>
			<origin xyz="0 0 0"/>
			<geometry>
				<mesh filename="textured_objs/original-61.obj"/>
			</geometry>
		</collision>
	</link>
	<joint name="joint_22" type="prismatic">
		<origin xyz="0 0 0"/>
		<axis xyz="0 0 -1"/>
		<child link="link_22"/>
		<parent link="link_42"/>
		<limit lower="0" upper="0.01"/>
	</joint>
	<link name="link_23">
		<visual name="button-24">
			<origin xyz="0 0 0"/>
			<geometry>
				<mesh filename="textured_objs/original-72.obj"/>
			</geometry>
		</visual>
		<visual name="button-24">
			<origin xyz="0 0 0"/>
			<geometry>
				<mesh filename="textured_objs/original-73.obj"/>
			</geometry>
		</visual>
		<visual name="button-24">
			<origin xyz="0 0 0"/>
			<geometry>
				<mesh filename="textured_objs/original-74.obj"/>
			</geometry>
		</visual>
		<visual name="button-24">
			<origin xyz="0 0 0"/>
			<geometry>
				<mesh filename="textured_objs/original-75.obj"/>
			</geometry>
		</visual>
		<visual name="button-24">
			<origin xyz="0 0 0"/>
			<geometry>
				<mesh filename="textured_objs/original-77.obj"/>
			</geometry>
		</visual>
		<visual name="button-24">
			<origin xyz="0 0 0"/>
			<geometry>
				<mesh filename="textured_objs/original-76.obj"/>
			</geometry>
		</visual>
		<collision>
			<origin xyz="0 0 0"/>
			<geometry>
				<mesh filename="textured_objs/original-72.obj"/>
			</geometry>
		</collision>
		<collision>
			<origin xyz="0 0 0"/>
			<geometry>
				<mesh filename="textured_objs/original-73.obj"/>
			</geometry>
		</collision>
		<collision>
			<origin xyz="0 0 0"/>
			<geometry>
				<mesh filename="textured_objs/original-74.obj"/>
			</geometry>
		</collision>
		<collision>
			<origin xyz="0 0 0"/>
			<geometry>
				<mesh filename="textured_objs/original-75.obj"/>
			</geometry>
		</collision>
		<collision>
			<origin xyz="0 0 0"/>
			<geometry>
				<mesh filename="textured_objs/original-77.obj"/>
			</geometry>
		</collision>
		<collision>
			<origin xyz="0 0 0"/>
			<geometry>
				<mesh filename="textured_objs/original-76.obj"/>
			</geometry>
		</collision>
	</link>
	<joint name="joint_23" type="prismatic">
		<origin xyz="0 0 0"/>
		<axis xyz="0 0 -1"/>
		<child link="link_23"/>
		<parent link="link_42"/>
		<limit lower="0" upper="0.01"/>
	</joint>
	<link name="link_24">
		<visual name="button-25">
			<origin xyz="-0.2275651375875013 -0.16 -0.09"/>
			<geometry>
				<mesh filename="textured_objs/original-179.obj"/>
			</geometry>
		</visual>
		<visual name="button-25">
			<origin xyz="-0.2275651375875013 -0.16 -0.09"/>
			<geometry>
				<mesh filename="textured_objs/original-178.obj"/>
			</geometry>
		</visual>
		<visual name="button-25">
			<origin xyz="-0.2275651375875013 -0.16 -0.09"/>
			<geometry>
				<mesh filename="textured_objs/original-180.obj"/>
			</geometry>
		</visual>
		<collision>
			<origin xyz="-0.2275651375875013 -0.16 -0.09"/>
			<geometry>
				<mesh filename="textured_objs/original-179.obj"/>
			</geometry>
		</collision>
		<collision>
			<origin xyz="-0.2275651375875013 -0.16 -0.09"/>
			<geometry>
				<mesh filename="textured_objs/original-178.obj"/>
			</geometry>
		</collision>
		<collision>
			<origin xyz="-0.2275651375875013 -0.16 -0.09"/>
			<geometry>
				<mesh filename="textured_objs/original-180.obj"/>
			</geometry>
		</collision>
	</link>
	<joint name="joint_24" type="revolute">
		<origin xyz="0.2275651375875013 0.16 0.09"/>
		<axis xyz="1 0 0"/>
		<child link="link_24"/>
		<parent link="link_42"/>
		<limit lower="-0.08726646259971647" upper="0.08726646259971647"/>
	</joint>
	<link name="link_25">
		<visual name="button-26">
			<origin xyz="0 0 0"/>
			<geometry>
				<mesh filename="textured_objs/original-22.obj"/>
			</geometry>
		</visual>
		<visual name="button-26">
			<origin xyz="0 0 0"/>
			<geometry>
				<mesh filename="textured_objs/original-28.obj"/>
			</geometry>
		</visual>
		<visual name="button-26">
			<origin xyz="0 0 0"/>
			<geometry>
				<mesh filename="textured_objs/original-24.obj"/>
			</geometry>
		</visual>
		<visual name="button-26">
			<origin xyz="0 0 0"/>
			<geometry>
				<mesh filename="textured_objs/original-25.obj"/>
			</geometry>
		</visual>
		<visual name="button-26">
			<origin xyz="0 0 0"/>
			<geometry>
				<mesh filename="textured_objs/original-26.obj"/>
			</geometry>
		</visual>
		<visual name="button-26">
			<origin xyz="0 0 0"/>
			<geometry>
				<mesh filename="textured_objs/original-27.obj"/>
			</geometry>
		</visual>
		<visual name="button-26">
			<origin xyz="0 0 0"/>
			<geometry>
				<mesh filename="textured_objs/original-23.obj"/>
			</geometry>
		</visual>
		<collision>
			<origin xyz="0 0 0"/>
			<geometry>
				<mesh filename="textured_objs/original-22.obj"/>
			</geometry>
		</collision>
		<collision>
			<origin xyz="0 0 0"/>
			<geometry>
				<mesh filename="textured_objs/original-28.obj"/>
			</geometry>
		</collision>
		<collision>
			<origin xyz="0 0 0"/>
			<geometry>
				<mesh filename="textured_objs/original-24.obj"/>
			</geometry>
		</collision>
		<collision>
			<origin xyz="0 0 0"/>
			<geometry>
				<mesh filename="textured_objs/original-25.obj"/>
			</geometry>
		</collision>
		<collision>
			<origin xyz="0 0 0"/>
			<geometry>
				<mesh filename="textured_objs/original-26.obj"/>
			</geometry>
		</collision>
		<collision>
			<origin xyz="0 0 0"/>
			<geometry>
				<mesh filename="textured_objs/original-27.obj"/>
			</geometry>
		</collision>
		<collision>
			<origin xyz="0 0 0"/>
			<geometry>
				<mesh filename="textured_objs/original-23.obj"/>
			</geometry>
		</collision>
	</link>
	<joint name="joint_25" type="prismatic">
		<origin xyz="0 0 0"/>
		<axis xyz="0 0 -1"/>
		<child link="link_25"/>
		<parent link="link_42"/>
		<limit lower="0" upper="0.01"/>
	</joint>
	<link name="link_26">
		<visual name="button-27">
			<origin xyz="0 0 0"/>
			<geometry>
				<mesh filename="textured_objs/original-31.obj"/>
			</geometry>
		</visual>
		<visual name="button-27">
			<origin xyz="0 0 0"/>
			<geometry>
				<mesh filename="textured_objs/original-32.obj"/>
			</geometry>
		</visual>
		<visual name="button-27">
			<origin xyz="0 0 0"/>
			<geometry>
				<mesh filename="textured_objs/original-34.obj"/>
			</geometry>
		</visual>
		<visual name="button-27">
			<origin xyz="0 0 0"/>
			<geometry>
				<mesh filename="textured_objs/original-35.obj"/>
			</geometry>
		</visual>
		<visual name="button-27">
			<origin xyz="0 0 0"/>
			<geometry>
				<mesh filename="textured_objs/original-33.obj"/>
			</geometry>
		</visual>
		<collision>
			<origin xyz="0 0 0"/>
			<geometry>
				<mesh filename="textured_objs/original-31.obj"/>
			</geometry>
		</collision>
		<collision>
			<origin xyz="0 0 0"/>
			<geometry>
				<mesh filename="textured_objs/original-32.obj"/>
			</geometry>
		</collision>
		<collision>
			<origin xyz="0 0 0"/>
			<geometry>
				<mesh filename="textured_objs/original-34.obj"/>
			</geometry>
		</collision>
		<collision>
			<origin xyz="0 0 0"/>
			<geometry>
				<mesh filename="textured_objs/original-35.obj"/>
			</geometry>
		</collision>
		<collision>
			<origin xyz="0 0 0"/>
			<geometry>
				<mesh filename="textured_objs/original-33.obj"/>
			</geometry>
		</collision>
	</link>
	<joint name="joint_26" type="prismatic">
		<origin xyz="0 0 0"/>
		<axis xyz="0 0 -1"/>
		<child link="link_26"/>
		<parent link="link_42"/>
		<limit lower="0" upper="0.01"/>
	</joint>
	<link name="link_27">
		<visual name="button-28">
			<origin xyz="-0.2275651375875013 -0.16 -0.09"/>
			<geometry>
				<mesh filename="textured_objs/original-181.obj"/>
			</geometry>
		</visual>
		<visual name="button-28">
			<origin xyz="-0.2275651375875013 -0.16 -0.09"/>
			<geometry>
				<mesh filename="textured_objs/original-182.obj"/>
			</geometry>
		</visual>
		<visual name="button-28">
			<origin xyz="-0.2275651375875013 -0.16 -0.09"/>
			<geometry>
				<mesh filename="textured_objs/original-183.obj"/>
			</geometry>
		</visual>
		<collision>
			<origin xyz="-0.2275651375875013 -0.16 -0.09"/>
			<geometry>
				<mesh filename="textured_objs/original-181.obj"/>
			</geometry>
		</collision>
		<collision>
			<origin xyz="-0.2275651375875013 -0.16 -0.09"/>
			<geometry>
				<mesh filename="textured_objs/original-182.obj"/>
			</geometry>
		</collision>
		<collision>
			<origin xyz="-0.2275651375875013 -0.16 -0.09"/>
			<geometry>
				<mesh filename="textured_objs/original-183.obj"/>
			</geometry>
		</collision>
	</link>
	<joint name="joint_27" type="revolute">
		<origin xyz="0.2275651375875013 0.16 0.09"/>
		<axis xyz="1 0 0"/>
		<child link="link_27"/>
		<parent link="link_42"/>
		<limit lower="-0.08726646259971647" upper="0.08726646259971647"/>
	</joint>
	<link name="link_28">
		<visual name="button-29">
			<origin xyz="0 0 0"/>
			<geometry>
				<mesh filename="textured_objs/original-3.obj"/>
			</geometry>
		</visual>
		<visual name="button-29">
			<origin xyz="0 0 0"/>
			<geometry>
				<mesh filename="textured_objs/original-2.obj"/>
			</geometry>
		</visual>
		<collision>
			<origin xyz="0 0 0"/>
			<geometry>
				<mesh filename="textured_objs/original-3.obj"/>
			</geometry>
		</collision>
		<collision>
			<origin xyz="0 0 0"/>
			<geometry>
				<mesh filename="textured_objs/original-2.obj"/>
			</geometry>
		</collision>
	</link>
	<joint name="joint_28" type="prismatic">
		<origin xyz="0 0 0"/>
		<axis xyz="0 0 -1"/>
		<child link="link_28"/>
		<parent link="link_42"/>
		<limit lower="0" upper="0.01"/>
	</joint>
	<link name="link_29">
		<visual name="button-30">
			<origin xyz="0 0 0"/>
			<geometry>
				<mesh filename="textured_objs/original-10.obj"/>
			</geometry>
		</visual>
		<visual name="button-30">
			<origin xyz="0 0 0"/>
			<geometry>
				<mesh filename="textured_objs/original-9.obj"/>
			</geometry>
		</visual>
		<collision>
			<origin xyz="0 0 0"/>
			<geometry>
				<mesh filename="textured_objs/original-10.obj"/>
			</geometry>
		</collision>
		<collision>
			<origin xyz="0 0 0"/>
			<geometry>
				<mesh filename="textured_objs/original-9.obj"/>
			</geometry>
		</collision>
	</link>
	<joint name="joint_29" type="prismatic">
		<origin xyz="0 0 0"/>
		<axis xyz="0 0 -1"/>
		<child link="link_29"/>
		<parent link="link_42"/>
		<limit lower="0" upper="0.01"/>
	</joint>
	<link name="link_30">
		<visual name="button-31">
			<origin xyz="0 0 0"/>
			<geometry>
				<mesh filename="textured_objs/original-13.obj"/>
			</geometry>
		</visual>
		<visual name="button-31">
			<origin xyz="0 0 0"/>
			<geometry>
				<mesh filename="textured_objs/original-14.obj"/>
			</geometry>
		</visual>
		<visual name="button-31">
			<origin xyz="0 0 0"/>
			<geometry>
				<mesh filename="textured_objs/original-15.obj"/>
			</geometry>
		</visual>
		<visual name="button-31">
			<origin xyz="0 0 0"/>
			<geometry>
				<mesh filename="textured_objs/original-17.obj"/>
			</geometry>
		</visual>
		<visual name="button-31">
			<origin xyz="0 0 0"/>
			<geometry>
				<mesh filename="textured_objs/original-19.obj"/>
			</geometry>
		</visual>
		<visual name="button-31">
			<origin xyz="0 0 0"/>
			<geometry>
				<mesh filename="textured_objs/original-16.obj"/>
			</geometry>
		</visual>
		<visual name="button-31">
			<origin xyz="0 0 0"/>
			<geometry>
				<mesh filename="textured_objs/original-18.obj"/>
			</geometry>
		</visual>
		<collision>
			<origin xyz="0 0 0"/>
			<geometry>
				<mesh filename="textured_objs/original-13.obj"/>
			</geometry>
		</collision>
		<collision>
			<origin xyz="0 0 0"/>
			<geometry>
				<mesh filename="textured_objs/original-14.obj"/>
			</geometry>
		</collision>
		<collision>
			<origin xyz="0 0 0"/>
			<geometry>
				<mesh filename="textured_objs/original-15.obj"/>
			</geometry>
		</collision>
		<collision>
			<origin xyz="0 0 0"/>
			<geometry>
				<mesh filename="textured_objs/original-17.obj"/>
			</geometry>
		</collision>
		<collision>
			<origin xyz="0 0 0"/>
			<geometry>
				<mesh filename="textured_objs/original-19.obj"/>
			</geometry>
		</collision>
		<collision>
			<origin xyz="0 0 0"/>
			<geometry>
				<mesh filename="textured_objs/original-16.obj"/>
			</geometry>
		</collision>
		<collision>
			<origin xyz="0 0 0"/>
			<geometry>
				<mesh filename="textured_objs/original-18.obj"/>
			</geometry>
		</collision>
	</link>
	<joint name="joint_30" type="prismatic">
		<origin xyz="0 0 0"/>
		<axis xyz="0 0 -1"/>
		<child link="link_30"/>
		<parent link="link_42"/>
		<limit lower="0" upper="0.01"/>
	</joint>
	<link name="link_31">
		<visual name="button-32">
			<origin xyz="0 0 0"/>
			<geometry>
				<mesh filename="textured_objs/original-113.obj"/>
			</geometry>
		</visual>
		<visual name="button-32">
			<origin xyz="0 0 0"/>
			<geometry>
				<mesh filename="textured_objs/original-112.obj"/>
			</geometry>
		</visual>
		<collision>
			<origin xyz="0 0 0"/>
			<geometry>
				<mesh filename="textured_objs/original-113.obj"/>
			</geometry>
		</collision>
		<collision>
			<origin xyz="0 0 0"/>
			<geometry>
				<mesh filename="textured_objs/original-112.obj"/>
			</geometry>
		</collision>
	</link>
	<joint name="joint_31" type="prismatic">
		<origin xyz="0 0 0"/>
		<axis xyz="0 0 -1"/>
		<child link="link_31"/>
		<parent link="link_42"/>
		<limit lower="0" upper="0.01"/>
	</joint>
	<link name="link_32">
		<visual name="button-33">
			<origin xyz="0 0 0"/>
			<geometry>
				<mesh filename="textured_objs/original-107.obj"/>
			</geometry>
		</visual>
		<visual name="button-33">
			<origin xyz="0 0 0"/>
			<geometry>
				<mesh filename="textured_objs/original-106.obj"/>
			</geometry>
		</visual>
		<collision>
			<origin xyz="0 0 0"/>
			<geometry>
				<mesh filename="textured_objs/original-107.obj"/>
			</geometry>
		</collision>
		<collision>
			<origin xyz="0 0 0"/>
			<geometry>
				<mesh filename="textured_objs/original-106.obj"/>
			</geometry>
		</collision>
	</link>
	<joint name="joint_32" type="prismatic">
		<origin xyz="0 0 0"/>
		<axis xyz="0 0 -1"/>
		<child link="link_32"/>
		<parent link="link_42"/>
		<limit lower="0" upper="0.01"/>
	</joint>
	<link name="link_33">
		<visual name="button-34">
			<origin xyz="0 0 0"/>
			<geometry>
				<mesh filename="textured_objs/original-110.obj"/>
			</geometry>
		</visual>
		<visual name="button-34">
			<origin xyz="0 0 0"/>
			<geometry>
				<mesh filename="textured_objs/original-109.obj"/>
			</geometry>
		</visual>
		<collision>
			<origin xyz="0 0 0"/>
			<geometry>
				<mesh filename="textured_objs/original-110.obj"/>
			</geometry>
		</collision>
		<collision>
			<origin xyz="0 0 0"/>
			<geometry>
				<mesh filename="textured_objs/original-109.obj"/>
			</geometry>
		</collision>
	</link>
	<joint name="joint_33" type="prismatic">
		<origin xyz="0 0 0"/>
		<axis xyz="0 0 -1"/>
		<child link="link_33"/>
		<parent link="link_42"/>
		<limit lower="0" upper="0.01"/>
	</joint>
	<link name="link_34">
		<visual name="button-35">
			<origin xyz="0 0 0"/>
			<geometry>
				<mesh filename="textured_objs/original-86.obj"/>
			</geometry>
		</visual>
		<visual name="button-35">
			<origin xyz="0 0 0"/>
			<geometry>
				<mesh filename="textured_objs/original-85.obj"/>
			</geometry>
		</visual>
		<collision>
			<origin xyz="0 0 0"/>
			<geometry>
				<mesh filename="textured_objs/original-86.obj"/>
			</geometry>
		</collision>
		<collision>
			<origin xyz="0 0 0"/>
			<geometry>
				<mesh filename="textured_objs/original-85.obj"/>
			</geometry>
		</collision>
	</link>
	<joint name="joint_34" type="prismatic">
		<origin xyz="0 0 0"/>
		<axis xyz="0 0 -1"/>
		<child link="link_34"/>
		<parent link="link_42"/>
		<limit lower="0" upper="0.01"/>
	</joint>
	<link name="link_35">
		<visual name="button-36">
			<origin xyz="0 0 0"/>
			<geometry>
				<mesh filename="textured_objs/original-101.obj"/>
			</geometry>
		</visual>
		<visual name="button-36">
			<origin xyz="0 0 0"/>
			<geometry>
				<mesh filename="textured_objs/original-100.obj"/>
			</geometry>
		</visual>
		<collision>
			<origin xyz="0 0 0"/>
			<geometry>
				<mesh filename="textured_objs/original-101.obj"/>
			</geometry>
		</collision>
		<collision>
			<origin xyz="0 0 0"/>
			<geometry>
				<mesh filename="textured_objs/original-100.obj"/>
			</geometry>
		</collision>
	</link>
	<joint name="joint_35" type="prismatic">
		<origin xyz="0 0 0"/>
		<axis xyz="0 0 -1"/>
		<child link="link_35"/>
		<parent link="link_42"/>
		<limit lower="0" upper="0.01"/>
	</joint>
	<link name="link_36">
		<visual name="button-37">
			<origin xyz="0 0 0"/>
			<geometry>
				<mesh filename="textured_objs/original-97.obj"/>
			</geometry>
		</visual>
		<visual name="button-37">
			<origin xyz="0 0 0"/>
			<geometry>
				<mesh filename="textured_objs/original-98.obj"/>
			</geometry>
		</visual>
		<collision>
			<origin xyz="0 0 0"/>
			<geometry>
				<mesh filename="textured_objs/original-97.obj"/>
			</geometry>
		</collision>
		<collision>
			<origin xyz="0 0 0"/>
			<geometry>
				<mesh filename="textured_objs/original-98.obj"/>
			</geometry>
		</collision>
	</link>
	<joint name="joint_36" type="prismatic">
		<origin xyz="0 0 0"/>
		<axis xyz="0 0 -1"/>
		<child link="link_36"/>
		<parent link="link_42"/>
		<limit lower="0" upper="0.01"/>
	</joint>
	<link name="link_37">
		<visual name="button-38">
			<origin xyz="0 0 0"/>
			<geometry>
				<mesh filename="textured_objs/original-6.obj"/>
			</geometry>
		</visual>
		<visual name="button-38">
			<origin xyz="0 0 0"/>
			<geometry>
				<mesh filename="textured_objs/original-5.obj"/>
			</geometry>
		</visual>
		<collision>
			<origin xyz="0 0 0"/>
			<geometry>
				<mesh filename="textured_objs/original-6.obj"/>
			</geometry>
		</collision>
		<collision>
			<origin xyz="0 0 0"/>
			<geometry>
				<mesh filename="textured_objs/original-5.obj"/>
			</geometry>
		</collision>
	</link>
	<joint name="joint_37" type="prismatic">
		<origin xyz="0 0 0"/>
		<axis xyz="0 0 -1"/>
		<child link="link_37"/>
		<parent link="link_42"/>
		<limit lower="0" upper="0.01"/>
	</joint>
	<link name="link_38">
		<visual name="button-39">
			<origin xyz="0 0 0"/>
			<geometry>
				<mesh filename="textured_objs/original-83.obj"/>
			</geometry>
		</visual>
		<visual name="button-39">
			<origin xyz="0 0 0"/>
			<geometry>
				<mesh filename="textured_objs/original-82.obj"/>
			</geometry>
		</visual>
		<collision>
			<origin xyz="0 0 0"/>
			<geometry>
				<mesh filename="textured_objs/original-83.obj"/>
			</geometry>
		</collision>
		<collision>
			<origin xyz="0 0 0"/>
			<geometry>
				<mesh filename="textured_objs/original-82.obj"/>
			</geometry>
		</collision>
	</link>
	<joint name="joint_38" type="prismatic">
		<origin xyz="0 0 0"/>
		<axis xyz="0 0 -1"/>
		<child link="link_38"/>
		<parent link="link_42"/>
		<limit lower="0" upper="0.01"/>
	</joint>
	<link name="link_39">
		<visual name="button-40">
			<origin xyz="0 0 0"/>
			<geometry>
				<mesh filename="textured_objs/original-104.obj"/>
			</geometry>
		</visual>
		<visual name="button-40">
			<origin xyz="0 0 0"/>
			<geometry>
				<mesh filename="textured_objs/original-103.obj"/>
			</geometry>
		</visual>
		<collision>
			<origin xyz="0 0 0"/>
			<geometry>
				<mesh filename="textured_objs/original-104.obj"/>
			</geometry>
		</collision>
		<collision>
			<origin xyz="0 0 0"/>
			<geometry>
				<mesh filename="textured_objs/original-103.obj"/>
			</geometry>
		</collision>
	</link>
	<joint name="joint_39" type="prismatic">
		<origin xyz="0 0 0"/>
		<axis xyz="0 0 -1"/>
		<child link="link_39"/>
		<parent link="link_42"/>
		<limit lower="0" upper="0.01"/>
	</joint>
	<link name="link_40">
		<visual name="button-41">
			<origin xyz="0 0 0"/>
			<geometry>
				<mesh filename="textured_objs/original-192.obj"/>
			</geometry>
		</visual>
		<visual name="button-41">
			<origin xyz="0 0 0"/>
			<geometry>
				<mesh filename="textured_objs/original-193.obj"/>
			</geometry>
		</visual>
		<visual name="button-41">
			<origin xyz="0 0 0"/>
			<geometry>
				<mesh filename="textured_objs/original-89.obj"/>
			</geometry>
		</visual>
		<visual name="button-41">
			<origin xyz="0 0 0"/>
			<geometry>
				<mesh filename="textured_objs/original-91.obj"/>
			</geometry>
		</visual>
		<visual name="button-41">
			<origin xyz="0 0 0"/>
			<geometry>
				<mesh filename="textured_objs/original-92.obj"/>
			</geometry>
		</visual>
		<visual name="button-41">
			<origin xyz="0 0 0"/>
			<geometry>
				<mesh filename="textured_objs/original-94.obj"/>
			</geometry>
		</visual>
		<visual name="button-41">
			<origin xyz="0 0 0"/>
			<geometry>
				<mesh filename="textured_objs/original-191.obj"/>
			</geometry>
		</visual>
		<visual name="button-41">
			<origin xyz="0 0 0"/>
			<geometry>
				<mesh filename="textured_objs/original-93.obj"/>
			</geometry>
		</visual>
		<visual name="button-41">
			<origin xyz="0 0 0"/>
			<geometry>
				<mesh filename="textured_objs/original-90.obj"/>
			</geometry>
		</visual>
		<collision>
			<origin xyz="0 0 0"/>
			<geometry>
				<mesh filename="textured_objs/original-192.obj"/>
			</geometry>
		</collision>
		<collision>
			<origin xyz="0 0 0"/>
			<geometry>
				<mesh filename="textured_objs/original-193.obj"/>
			</geometry>
		</collision>
		<collision>
			<origin xyz="0 0 0"/>
			<geometry>
				<mesh filename="textured_objs/original-89.obj"/>
			</geometry>
		</collision>
		<collision>
			<origin xyz="0 0 0"/>
			<geometry>
				<mesh filename="textured_objs/original-91.obj"/>
			</geometry>
		</collision>
		<collision>
			<origin xyz="0 0 0"/>
			<geometry>
				<mesh filename="textured_objs/original-92.obj"/>
			</geometry>
		</collision>
		<collision>
			<origin xyz="0 0 0"/>
			<geometry>
				<mesh filename="textured_objs/original-94.obj"/>
			</geometry>
		</collision>
		<collision>
			<origin xyz="0 0 0"/>
			<geometry>
				<mesh filename="textured_objs/original-191.obj"/>
			</geometry>
		</collision>
		<collision>
			<origin xyz="0 0 0"/>
			<geometry>
				<mesh filename="textured_objs/original-93.obj"/>
			</geometry>
		</collision>
		<collision>
			<origin xyz="0 0 0"/>
			<geometry>
				<mesh filename="textured_objs/original-90.obj"/>
			</geometry>
		</collision>
	</link>
	<joint name="joint_40" type="prismatic">
		<origin xyz="0 0 0"/>
		<axis xyz="0 0 -1"/>
		<child link="link_40"/>
		<parent link="link_42"/>
		<limit lower="0" upper="0.01"/>
	</joint>
	<link name="link_41">
		<visual name="button-42">
			<origin xyz="0 0 0"/>
			<geometry>
				<mesh filename="textured_objs/original-177.obj"/>
			</geometry>
		</visual>
		<visual name="button-42">
			<origin xyz="0 0 0"/>
			<geometry>
				<mesh filename="textured_objs/original-175.obj"/>
			</geometry>
		</visual>
		<visual name="button-42">
			<origin xyz="0 0 0"/>
			<geometry>
				<mesh filename="textured_objs/original-176.obj"/>
			</geometry>
		</visual>
		<collision>
			<origin xyz="0 0 0"/>
			<geometry>
				<mesh filename="textured_objs/original-177.obj"/>
			</geometry>
		</collision>
		<collision>
			<origin xyz="0 0 0"/>
			<geometry>
				<mesh filename="textured_objs/original-175.obj"/>
			</geometry>
		</collision>
		<collision>
			<origin xyz="0 0 0"/>
			<geometry>
				<mesh filename="textured_objs/original-176.obj"/>
			</geometry>
		</collision>
	</link>
	<joint name="joint_41" type="prismatic">
		<origin xyz="0 0 0"/>
		<axis xyz="0 0 -1"/>
		<child link="link_41"/>
		<parent link="link_42"/>
		<limit lower="0" upper="0.01"/>
	</joint>
	<link name="link_42">
		<visual name="base_body-43">
			<origin xyz="0 0 0"/>
			<geometry>
				<mesh filename="textured_objs/original-196.obj"/>
			</geometry>
		</visual>
		<visual name="base_body-43">
			<origin xyz="0 0 0"/>
			<geometry>
				<mesh filename="textured_objs/original-214.obj"/>
			</geometry>
		</visual>
		<visual name="base_body-43">
			<origin xyz="0 0 0"/>
			<geometry>
				<mesh filename="textured_objs/original-217.obj"/>
			</geometry>
		</visual>
		<visual name="base_body-43">
			<origin xyz="0 0 0"/>
			<geometry>
				<mesh filename="textured_objs/original-216.obj"/>
			</geometry>
		</visual>
		<visual name="base_body-43">
			<origin xyz="0 0 0"/>
			<geometry>
				<mesh filename="textured_objs/original-213.obj"/>
			</geometry>
		</visual>
		<visual name="base_body-43">
			<origin xyz="0 0 0"/>
			<geometry>
				<mesh filename="textured_objs/original-218.obj"/>
			</geometry>
		</visual>
		<visual name="base_body-43">
			<origin xyz="0 0 0"/>
			<geometry>
				<mesh filename="textured_objs/original-215.obj"/>
			</geometry>
		</visual>
		<visual name="base_body-43">
			<origin xyz="0 0 0"/>
			<geometry>
				<mesh filename="textured_objs/original-194.obj"/>
			</geometry>
		</visual>
		<collision>
			<origin xyz="0 0 0"/>
			<geometry>
				<mesh filename="textured_objs/original-196.obj"/>
			</geometry>
		</collision>
		<collision>
			<origin xyz="0 0 0"/>
			<geometry>
				<mesh filename="textured_objs/original-214.obj"/>
			</geometry>
		</collision>
		<collision>
			<origin xyz="0 0 0"/>
			<geometry>
				<mesh filename="textured_objs/original-217.obj"/>
			</geometry>
		</collision>
		<collision>
			<origin xyz="0 0 0"/>
			<geometry>
				<mesh filename="textured_objs/original-216.obj"/>
			</geometry>
		</collision>
		<collision>
			<origin xyz="0 0 0"/>
			<geometry>
				<mesh filename="textured_objs/original-213.obj"/>
			</geometry>
		</collision>
		<collision>
			<origin xyz="0 0 0"/>
			<geometry>
				<mesh filename="textured_objs/original-218.obj"/>
			</geometry>
		</collision>
		<collision>
			<origin xyz="0 0 0"/>
			<geometry>
				<mesh filename="textured_objs/original-215.obj"/>
			</geometry>
		</collision>
		<collision>
			<origin xyz="0 0 0"/>
			<geometry>
				<mesh filename="textured_objs/original-194.obj"/>
			</geometry>
		</collision>
	</link>
	<joint name="joint_42" type="fixed">
		<origin rpy="1.570796326794897 0 -1.570796326794897" xyz="0 0 0"/>
		<child link="link_42"/>
		<parent link="base"/>
	</joint>
</robot>
