<?xml version="1.0" ?>
<robot name="partnet_96c6742a47bd5e451021cd55d164c0ed">
	<link name="base"/>
	<link name="link_0">
		<visual name="door-1">
			<origin xyz="0.36159165317299186 -0.6568700000000003 -0.3084953358260058"/>
			<geometry>
				<mesh filename="textured_objs/original-15.obj"/>
			</geometry>
		</visual>
		<visual name="door-1">
			<origin xyz="0.36159165317299186 -0.6568700000000003 -0.3084953358260058"/>
			<geometry>
				<mesh filename="textured_objs/original-4.obj"/>
			</geometry>
		</visual>
		<visual name="door-1">
			<origin xyz="0.36159165317299186 -0.6568700000000003 -0.3084953358260058"/>
			<geometry>
				<mesh filename="textured_objs/original-2.obj"/>
			</geometry>
		</visual>
		<visual name="door-1">
			<origin xyz="0.36159165317299186 -0.6568700000000003 -0.3084953358260058"/>
			<geometry>
				<mesh filename="textured_objs/original-24.obj"/>
			</geometry>
		</visual>
		<visual name="door-1">
			<origin xyz="0.36159165317299186 -0.6568700000000003 -0.3084953358260058"/>
			<geometry>
				<mesh filename="textured_objs/original-3.obj"/>
			</geometry>
		</visual>
		<visual name="door-1">
			<origin xyz="0.36159165317299186 -0.6568700000000003 -0.3084953358260058"/>
			<geometry>
				<mesh filename="textured_objs/original-12.obj"/>
			</geometry>
		</visual>
		<visual name="door-1">
			<origin xyz="0.36159165317299186 -0.6568700000000003 -0.3084953358260058"/>
			<geometry>
				<mesh filename="textured_objs/original-27.obj"/>
			</geometry>
		</visual>
		<visual name="door-1">
			<origin xyz="0.36159165317299186 -0.6568700000000003 -0.3084953358260058"/>
			<geometry>
				<mesh filename="textured_objs/original-26.obj"/>
			</geometry>
		</visual>
		<visual name="door-1">
			<origin xyz="0.36159165317299186 -0.6568700000000003 -0.3084953358260058"/>
			<geometry>
				<mesh filename="textured_objs/original-25.obj"/>
			</geometry>
		</visual>
		<collision>
			<origin xyz="0.36159165317299186 -0.6568700000000003 -0.3084953358260058"/>
			<geometry>
				<mesh filename="textured_objs/original-15.obj"/>
			</geometry>
		</collision>
		<collision>
			<origin xyz="0.36159165317299186 -0.6568700000000003 -0.3084953358260058"/>
			<geometry>
				<mesh filename="textured_objs/original-4.obj"/>
			</geometry>
		</collision>
		<collision>
			<origin xyz="0.36159165317299186 -0.6568700000000003 -0.3084953358260058"/>
			<geometry>
				<mesh filename="textured_objs/original-2.obj"/>
			</geometry>
		</collision>
		<collision>
			<origin xyz="0.36159165317299186 -0.6568700000000003 -0.3084953358260058"/>
			<geometry>
				<mesh filename="textured_objs/original-24.obj"/>
			</geometry>
		</collision>
		<collision>
			<origin xyz="0.36159165317299186 -0.6568700000000003 -0.3084953358260058"/>
			<geometry>
				<mesh filename="textured_objs/original-3.obj"/>
			</geometry>
		</collision>
		<collision>
			<origin xyz="0.36159165317299186 -0.6568700000000003 -0.3084953358260058"/>
			<geometry>
				<mesh filename="textured_objs/original-12.obj"/>
			</geometry>
		</collision>
		<collision>
			<origin xyz="0.36159165317299186 -0.6568700000000003 -0.3084953358260058"/>
			<geometry>
				<mesh filename="textured_objs/original-27.obj"/>
			</geometry>
		</collision>
		<collision>
			<origin xyz="0.36159165317299186 -0.6568700000000003 -0.3084953358260058"/>
			<geometry>
				<mesh filename="textured_objs/original-26.obj"/>
			</geometry>
		</collision>
		<collision>
			<origin xyz="0.36159165317299186 -0.6568700000000003 -0.3084953358260058"/>
			<geometry>
				<mesh filename="textured_objs/original-25.obj"/>
			</geometry>
		</collision>
	</link>
	<joint name="joint_0" type="revolute">
		<origin xyz="-0.36159165317299186 0.6568700000000003 0.3084953358260058"/>
		<axis xyz="0 -1 0"/>
		<child link="link_0"/>
		<parent link="link_2"/>
		<limit lower="-0.653451271946677" upper="2.0671679660620836"/>
	</joint>
	<link name="link_1">
		<visual name="switch-5">
			<origin xyz="-0.42107775936195097 -0.24051903976937045 -0.3471285005138152"/>
			<geometry>
				<mesh filename="textured_objs/original-28.obj"/>
			</geometry>
		</visual>
		<visual name="switch-5">
			<origin xyz="-0.42107775936195097 -0.24051903976937045 -0.3471285005138152"/>
			<geometry>
				<mesh filename="textured_objs/original-17.obj"/>
			</geometry>
		</visual>
		<visual name="switch-5">
			<origin xyz="-0.42107775936195097 -0.24051903976937045 -0.3471285005138152"/>
			<geometry>
				<mesh filename="textured_objs/original-14.obj"/>
			</geometry>
		</visual>
		<collision>
			<origin xyz="-0.42107775936195097 -0.24051903976937045 -0.3471285005138152"/>
			<geometry>
				<mesh filename="textured_objs/original-28.obj"/>
			</geometry>
		</collision>
		<collision>
			<origin xyz="-0.42107775936195097 -0.24051903976937045 -0.3471285005138152"/>
			<geometry>
				<mesh filename="textured_objs/original-17.obj"/>
			</geometry>
		</collision>
		<collision>
			<origin xyz="-0.42107775936195097 -0.24051903976937045 -0.3471285005138152"/>
			<geometry>
				<mesh filename="textured_objs/original-14.obj"/>
			</geometry>
		</collision>
	</link>
	<joint name="joint_1" type="continuous">
		<origin xyz="0.7826694125349428 -0.41635096023062984 0.03863316468780942"/>
		<axis xyz="-0.6360635966136855 -0.00010333123638589688 0.7716366310547463"/>
		<child link="link_1"/>
		<parent link="link_0"/>
	</joint>
	<link name="link_2">
		<visual name="base_body-8">
			<origin xyz="0 0 0"/>
			<geometry>
				<mesh filename="textured_objs/original-8.obj"/>
			</geometry>
		</visual>
		<visual name="base_body-8">
			<origin xyz="0 0 0"/>
			<geometry>
				<mesh filename="textured_objs/original-9.obj"/>
			</geometry>
		</visual>
		<visual name="base_body-8">
			<origin xyz="0 0 0"/>
			<geometry>
				<mesh filename="textured_objs/original-11.obj"/>
			</geometry>
		</visual>
		<visual name="base_body-8">
			<origin xyz="0 0 0"/>
			<geometry>
				<mesh filename="textured_objs/original-20.obj"/>
			</geometry>
		</visual>
		<visual name="base_body-8">
			<origin xyz="0 0 0"/>
			<geometry>
				<mesh filename="textured_objs/original-10.obj"/>
			</geometry>
		</visual>
		<collision>
			<origin xyz="0 0 0"/>
			<geometry>
				<mesh filename="textured_objs/original-8.obj"/>
			</geometry>
		</collision>
		<collision>
			<origin xyz="0 0 0"/>
			<geometry>
				<mesh filename="textured_objs/original-9.obj"/>
			</geometry>
		</collision>
		<collision>
			<origin xyz="0 0 0"/>
			<geometry>
				<mesh filename="textured_objs/original-11.obj"/>
			</geometry>
		</collision>
		<collision>
			<origin xyz="0 0 0"/>
			<geometry>
				<mesh filename="textured_objs/original-20.obj"/>
			</geometry>
		</collision>
		<collision>
			<origin xyz="0 0 0"/>
			<geometry>
				<mesh filename="textured_objs/original-10.obj"/>
			</geometry>
		</collision>
	</link>
	<joint name="joint_2" type="fixed">
		<origin rpy="1.570796326794897 0 -1.570796326794897" xyz="0 0 0"/>
		<child link="link_2"/>
		<parent link="base"/>
	</joint>
	<link name="link_3">
		<visual name="switch-2">
			<origin xyz="0.13639947629698213 0.016313575992393144 -0.6316314453069425"/>
			<geometry>
				<mesh filename="textured_objs/original-13.obj"/>
			</geometry>
		</visual>
		<visual name="switch-2">
			<origin xyz="0.13639947629698213 0.016313575992393144 -0.6316314453069425"/>
			<geometry>
				<mesh filename="textured_objs/original-29.obj"/>
			</geometry>
		</visual>
		<visual name="switch-2">
			<origin xyz="0.13639947629698213 0.016313575992393144 -0.6316314453069425"/>
			<geometry>
				<mesh filename="textured_objs/original-7.obj"/>
			</geometry>
		</visual>
		<visual name="outlier-6">
			<origin xyz="0.13639947629698213 0.016313575992393144 -0.6316314453069425"/>
			<geometry>
				<mesh filename="textured_objs/original-18.obj"/>
			</geometry>
		</visual>
		<visual name="outlier-6">
			<origin xyz="0.13639947629698213 0.016313575992393144 -0.6316314453069425"/>
			<geometry>
				<mesh filename="textured_objs/original-23.obj"/>
			</geometry>
		</visual>
		<visual name="outlier-6">
			<origin xyz="0.13639947629698213 0.016313575992393144 -0.6316314453069425"/>
			<geometry>
				<mesh filename="textured_objs/original-21.obj"/>
			</geometry>
		</visual>
		<visual name="outlier-6">
			<origin xyz="0.13639947629698213 0.016313575992393144 -0.6316314453069425"/>
			<geometry>
				<mesh filename="textured_objs/original-16.obj"/>
			</geometry>
		</visual>
		<visual name="outlier-6">
			<origin xyz="0.13639947629698213 0.016313575992393144 -0.6316314453069425"/>
			<geometry>
				<mesh filename="textured_objs/original-22.obj"/>
			</geometry>
		</visual>
		<visual name="outlier-7">
			<origin xyz="0.13639947629698213 0.016313575992393144 -0.6316314453069425"/>
			<geometry>
				<mesh filename="textured_objs/original-19.obj"/>
			</geometry>
		</visual>
		<collision>
			<origin xyz="0.13639947629698213 0.016313575992393144 -0.6316314453069425"/>
			<geometry>
				<mesh filename="textured_objs/original-13.obj"/>
			</geometry>
		</collision>
		<collision>
			<origin xyz="0.13639947629698213 0.016313575992393144 -0.6316314453069425"/>
			<geometry>
				<mesh filename="textured_objs/original-29.obj"/>
			</geometry>
		</collision>
		<collision>
			<origin xyz="0.13639947629698213 0.016313575992393144 -0.6316314453069425"/>
			<geometry>
				<mesh filename="textured_objs/original-7.obj"/>
			</geometry>
		</collision>
		<collision>
			<origin xyz="0.13639947629698213 0.016313575992393144 -0.6316314453069425"/>
			<geometry>
				<mesh filename="textured_objs/original-18.obj"/>
			</geometry>
		</collision>
		<collision>
			<origin xyz="0.13639947629698213 0.016313575992393144 -0.6316314453069425"/>
			<geometry>
				<mesh filename="textured_objs/original-23.obj"/>
			</geometry>
		</collision>
		<collision>
			<origin xyz="0.13639947629698213 0.016313575992393144 -0.6316314453069425"/>
			<geometry>
				<mesh filename="textured_objs/original-21.obj"/>
			</geometry>
		</collision>
		<collision>
			<origin xyz="0.13639947629698213 0.016313575992393144 -0.6316314453069425"/>
			<geometry>
				<mesh filename="textured_objs/original-16.obj"/>
			</geometry>
		</collision>
		<collision>
			<origin xyz="0.13639947629698213 0.016313575992393144 -0.6316314453069425"/>
			<geometry>
				<mesh filename="textured_objs/original-22.obj"/>
			</geometry>
		</collision>
		<collision>
			<origin xyz="0.13639947629698213 0.016313575992393144 -0.6316314453069425"/>
			<geometry>
				<mesh filename="textured_objs/original-19.obj"/>
			</geometry>
		</collision>
	</link>
	<joint name="joint_3" type="continuous">
		<origin xyz="0.22519217687600973 -0.6731835759923934 0.3231361094809367"/>
		<axis xyz="-0.6360772867448893 -9.110514783407116e-06 0.7716253528781041"/>
		<child link="link_3"/>
		<parent link="link_0"/>
	</joint>
</robot>
